Workbook
Name Alineamiento: 'A-D.- FICHA'!$G$49:$H$51
Name Alineamiento: #REF!
Name CatTipo: 'A-D.- FICHA'!$E$133:$R$133
Name CatTipo: #REF!
Name Cond.Borde: 'A-D.- FICHA'!$C$144:$C$150
Name Cond.Borde: #REF!
Name Cond.Carretera: 'A-D.- FICHA'!$J$375:$J$377
Name Cond.Carretera: #REF!
Name CondAmb: 'A-D.- FICHA'!$N$49:$N$51
Name CondAmb: #REF!
Name elementos: 'F.- ELEMENTOS'!$C$73:$J$184
Name FormaViga: 'A-D.- FICHA'!$L$153:$L$156
Name FormaViga: #REF!
Name luisa: 'A-D.- FICHA'!$C$161:$C$165
Name luisa: #REF!
Name MarcasdeCalzada: 'A-D.- FICHA'!$G$372
Name MarcasdeCalzada: #REF!
Name Mat: 'A-D.- FICHA'!$G$161:$G$164
Name Mat: #REF!
Name Mat.Predo: 'A-D.- FICHA'!$G$144:$G$150
Name Mat.Predo: #REF!
Name MatBaranda: 'A-D.- FICHA'!$G$282:$G$285
Name MatBaranda: #REF!
Name MatDrenaje: 'A-D.- FICHA'!$M$290:$M$293
Name MatDrenaje: #REF!
Name MaterialCimenta: 'A-D.- FICHA'!$N$161:$N$165
Name MaterialCimenta: #REF!
Name MaterialEleva: 'A-D.- FICHA'!$G$161:$G$164
Name MaterialEleva: #REF!
Name Materiallosa: 'A-D.- FICHA'!$J$144:$J$148
Name Materiallosa: #REF!
Name MatJuntas: 'A-D.- FICHA'!$F$290:$F$293
Name MatJuntas: #REF!
Name MatVeredas: 'A-D.- FICHA'!$J$282:$J$284
Name MatVeredas: #REF!
Name MatVigas: 'A-D.- FICHA'!$H$153:$H$157
Name MatVigas: #REF!
Name Nat.Suelo: 'A-D.- FICHA'!$N$375:$N$380
Name Nat.Suelo: #REF!
Name pendiente: #REF!
Name pendiente: #REF!
Name SeñaCarga: #REF!
Name SeñaCarga: #REF!
Name SeñalInformativa: 'A-D.- FICHA'!$G$360
Name SeñalInformativa: #REF!
Name Señalpreventiva: 'A-D.- FICHA'!$G$362:$G$365
Name Señalpreventiva: #REF!
Name SeñalReglamentaria: 'A-D.- FICHA'!$G$367:$G$370
Name SeñalReglamentaria: #REF!
Name Sobre: 'A-D.- FICHA'!$C$49:$E$56
Name Sobre: #REF!
Name Subestructura: 'A-D.- FICHA'!$G$375:$G$376
Name Subestructura: #REF!
Name SuperDesgaste: 'A-D.- FICHA'!$N$144:$N$148
Name SuperDesgaste: #REF!
Name TipoApoyos: 'A-D.- FICHA'!$N$282:$N$287
Name TipoApoyos: #REF!
Name TipoBarandas: 'A-D.- FICHA'!$C$282:$C$285
Name TipoBarandas: #REF!
Name TipoCimentación: 'A-D.- FICHA'!$J$161:$J$164

Sheet A-D.- FICHA
C4: PUENTE AGUA BLANCA
C6: SECCION (A) : IDENTIFICACIÓN Y UBICACIÓN
H9: Nombre | J9: =+C4 -> PUENTE AGUA BLANCA | N9: 1
H11: Código | J11: MO-100.002A | N11: 2
C13: Altitud: | E13: 1978 m | G13: 3 | H13: Dept Político: | J13: Moquegua | L13: 6 | N13: Poblado mas cercano | P13: =+J19 -> Matalaque | R13: 10
C15: C Este (19K) | E15: 311174.39 | G15: 4 | H15: Dept Vial | J15: Moquegua | L15: 7 | N15: Ruta | P15: MO-100 | R15: 11
C17: C Norte (19K) | E17: 8155443.4 | G17: 5 | H17: Provincia | J17: Gral. Sanchez Cerro | L17: 8 | N17: Kilometraje | P17: 30298 | R17: 12
C19: Tramo | E19: 11 | H19: Distrito | J19: Matalaque | L19: 9 | N19: Tipo de Ruta | P19: Departamental | R19: 13
C24: SECCION (B): DATOS GENERALES
C27: Puente sobre: | E27: Río | G27: 1 | J27: Número de Proyecto: | P27: 10
C29: Nombre: | E29: Tambo | G29: 2 | J29: Año de Construcción: | P29: 11
C31: Longitud Total: | E31: 31.2 | G31: 3 | J31: Última Inspección: | N31: 45715 | P31: 12 | R31: mm/dd/aa
C33: Num de vías de tránsito: | E33: 1 | G33: 4 | J33: Último Trabajo: | N33: Sin Informacion | P33: 13
C35: Ancho de Calzada: | E35: 3.5 | G35: 5 | J35: Tipo de Servicio: | N35: Camiones hasta Cierta Carga | R35: 14
C37: Sobrecarga de Diseño: | G37: 6 | J37: Flujo de Tráfico: | N37: 81 | P37: 15
C39: Ancho de Vereda: | E39: 0.6 | G39: 7 | J39: Año: | N39: 2025 | P39: 16
C41: Altura Libre Superior: | G41: 8 | J41: % Camiones y Buses: | N41: 0.09 | P41: 17
C43: Altura Libre Inferior: | E43: 5.63 | G43: 9 | J43: Alineamiento: | N43: Recto | P43: 18
J45: Condiciones Ambientales: | N45: Moderado | P45: 19
C47: Evaluación : Ing. Martín Pichón
C48: Sobre | G48: Alineamiento | J48: Tipo de Servicio | N48: Condiciones Ambientales
C49: Río | G49: Recto | J49: Irrestricto | N49: Severo
C50: Quebrada Seca | G50: Curvo | J50: Solo Automoviles | N50: Moderado | R50: Tipo de ruta
C51: Quebrada | G51: Esviado | J51: Solo Camiones | N51: Benigno | R51: Nacional
C52: Canal | J52: Camiones hasta Cierta Carga | R52: Departamental
C53: Carretera | J53: Fuera de Servicio | R53: Vecinal
C54: FFCC
C55: Valle (Viaducto Elevado)
C56: Zona Urbana (Viaducto elevado)
C59: SECCION (C): DATOS DEL PUENTE
C62: Num Tram: | E62: 1 | G62: 1 | H62: Long. 1ºTramo: | J62: =+E66 -> 31.2 | L62: 4
C64: Tramos: | E64: Iguales | G64: 2 | H64: Long. 2ºTramo: | J64: - | L64: 5
C66: Longitud Total: | E66: =+E31 -> 31.2 | G66: (Igual a B-3) | H66: Long. 3ºTramo: | J66: - | L66: 6
C68: Luz Principal: | E68: 30.45 | G68: 3
C72: C.1 : TRAMO 1 (PRINCIPAL) | J72: C.2 :TRAMO 2
C74: {Sección 1} | J74: {Sección 2} | L74: =+IF(E64="Desiguales","","(igual a Sección 1)") -> (igual a Sección 1) | U74: DEFINITIVO
C75: {Subsección a} | U75: Losa
C76: Categoría: | E76: DEFINITIVO | G76: 1 | J76: Categoría: | P76: 1 | U76: Losa con Vigas
U77: Portico
C78: Tipo : | E78: Losa con Vigas | G78: 2 | J78: Tipo : | P78: 2 | U78: Arco
...

Sheet E.- CROQUIS
B4: SECCION ( E ) : CROQUIS DEL PUENTE | C4: PUENTE AGUA BLANCA
B5: NOMBRE : | C5: =+'A-D.- FICHA'!J9 -> PUENTE AGUA BLANCA
B6: Ruta : | C6: =+'A-D.- FICHA'!P15 -> MO-100 | F6: Progresiva : | G6: =+'A-D.- FICHA'!P17 -> 30298
B8: ELEVACION
B22: PLANTA
B37: SECCION TRANSVERSAL
B51: =+'A-D.- FICHA'!C47 -> Evaluación : Ing. Martín Pichón

Sheet F.- ELEMENTOS
C4: PUENTE AGUA BLANCA
C6: F.1 : RELACION DE ELEMENTOS CONFORMANTES DEL PUENTE
C7: Nombre: | E7: =+'E.- CROQUIS'!C5 -> PUENTE AGUA BLANCA
C8: Ruta: | E8: =+'A-D.- FICHA'!P15 -> MO-100
C9: Progresiva: | E9: =+'A-D.- FICHA'!P17 -> 30298
G11: DESCRIPCIÓN | K11: Codigo | L11: Metrado | M11: UND. | N11: Importancia
C13: I. SUPERESTRUCTURA
D14: =+VLOOKUP(K14,$C$73:$J$184,3,FALSE) -> Losa de concreto armado (Refuerzo Transversal) | K14: 104 | L14: 29.328 | M14: =+VLOOKUP(K14,$C$73:$J$184,7,FALSE) -> m3 | N14: =+VLOOKUP(K14,$C$73:$J$184,8,FALSE) -> 0.6
D15: =+VLOOKUP(K15,$C$73:$J$184,3,FALSE) -> Viga Principales concreto armado | K15: 110 | L15: 66.05 | M15: =+VLOOKUP(K15,$C$73:$J$184,7,FALSE) -> m3 | N15: =+VLOOKUP(K15,$C$73:$J$184,8,FALSE) -> 1
D16: =+VLOOKUP(K16,$C$73:$J$184,3,FALSE) -> Vigas Secundarias de concreto armado | K16: 111 | L16: 6.5625 | M16: =+VLOOKUP(K16,$C$73:$J$184,7,FALSE) -> m3 | N16: =+VLOOKUP(K16,$C$73:$J$184,8,FALSE) -> 0.8
C18: II. SUBESTRUCTURA
D19: =+VLOOKUP(K19,$C$73:$J$184,3,FALSE) -> Elevación Cuerpo del Estribo de Concreto Armado | K19: 202 | L19: 120.132 | M19: =+VLOOKUP(K19,$C$73:$J$184,7,FALSE) -> m3 | N19: =+VLOOKUP(K19,$C$73:$J$184,8,FALSE) -> 1
D20: =+VLOOKUP(K20,$C$73:$J$184,3,FALSE) -> Elevación Alas del Estribo de Concreto Armado | K20: 205 | L20: 22.26 | M20: =+VLOOKUP(K20,$C$73:$J$184,7,FALSE) -> m3 | N20: =+VLOOKUP(K20,$C$73:$J$184,8,FALSE) -> 0.6
C22: III. DETALLES
D23: =+VLOOKUP(K23,$C$73:$J$184,3,FALSE) -> Capa Concreto Pobre | K23: 302 | L23: 109.2 | M23: =+VLOOKUP(K23,$C$73:$J$184,7,FALSE) -> m2 | N23: =+VLOOKUP(K23,$C$73:$J$184,8,FALSE) -> 0.4
D24: =+VLOOKUP(K24,$C$73:$J$184,3,FALSE) -> Vereda Concreto | K24: 311 | L24: 37.44 | M24: =+VLOOKUP(K24,$C$73:$J$184,7,FALSE) -> m2 | N24: =+VLOOKUP(K24,$C$73:$J$184,8,FALSE) -> 0.2
D25: =+VLOOKUP(K25,$C$73:$J$184,3,FALSE) -> Barandas de Acero | K25: 353 | L25: 62.4 | M25: =+VLOOKUP(K25,$C$73:$J$184,7,FALSE) -> ml | N25: =+VLOOKUP(K25,$C$73:$J$184,8,FALSE) -> 0.4
D26: =+VLOOKUP(K26,$C$73:$J$184,3,FALSE) -> Tuberías PVC | K26: 372 | L26: 12 | M26: =+VLOOKUP(K26,$C$73:$J$184,7,FALSE) -> und. | N26: =+VLOOKUP(K26,$C$73:$J$184,8,FALSE) -> 0.4
C28: IV. CAUCE
D29: =+VLOOKUP(K29,$C$73:$J$184,3,FALSE) -> Márgenes del río | K29: 401 | L29: 500 | M29: =+VLOOKUP(K29,$C$73:$J$184,7,FALSE) -> ml | N29: =+VLOOKUP(K29,$C$73:$J$184,8,FALSE) -> 0.6
D30: =+VLOOKUP(K30,$C$73:$J$184,3,FALSE) -> Lecho del río | K30: 402 | L30: 250 | M30: =+VLOOKUP(K30,$C$73:$J$184,7,FALSE) -> ml | N30: =+VLOOKUP(K30,$C$73:$J$184,8,FALSE) -> 0.6
C32: V. ACCESOS
D33: =+VLOOKUP(K33,$C$73:$J$184,3,FALSE) -> Señalización | K33: 501 | L33: 1 | M33: =+VLOOKUP(K33,$C$73:$J$184,7,FALSE) -> und. | N33: =+VLOOKUP(K33,$C$73:$J$184,8,FALSE) -> 0.2
D34: =+VLOOKUP(K34,$C$73:$J$184,3,FALSE) -> Pavimento/Afirmado | K34: 511 | L34: 70 | M34: =+VLOOKUP(K34,$C$73:$J$184,7,FALSE) -> m2 | N34: =+VLOOKUP(K34,$C$73:$J$184,8,FALSE) -> 0.2
D35: =+VLOOKUP(K35,$C$73:$J$184,3,FALSE) -> Visibilidad | K35: 530 | L35: 40 | M35: =+VLOOKUP(K35,$C$73:$J$184,7,FALSE) -> ml | N35: =+VLOOKUP(K35,$C$73:$J$184,8,FALSE) -> 0.2
C37: =+'A-D.- FICHA'!C47 -> Evaluación : Ing. Martín Pichón
B39: CUADRO DE LA CONDICION DE LOS ELEMENTOS
B40: PORCENTAJE DE EVALUACIÓN DE CAMPO DE CADA ELEMENTO DEL PUENTE
B42: Codigo | G42: CONDICION
B43: de | C43: METRADO | D43: unidad | E43: 5 | F43: 4 | G43: 3 | H43: 2 | I43: 1 | J43: 0 | K43: TOTAL | Q43: PORCENTAJE DE EVALUACIÓN DE CAMPO DE CADA ELEMENTO DEL PUENTE
B44: Elemento | E44: Pésimo | F44: Muy mal | G44: Mal | H44: Regular | I44: Bueno | J44: Muy Bueno | K44: %
A45: Losa de Conc. Armado (Ref. Longitudinal) | B45: 101 | D45: =+VLOOKUP(B45,$C$73:$J$184,7,FALSE) -> m3 | J45: 1 | K45: =SUM(E45:J45) -> 1
A46: Brida superior e inferior, Montantes y Diagonales | B46: 160 | D46: =+VLOOKUP(B46,$C$73:$J$184,7,FALSE) -> kg | J46: 1 | K46: =SUM(E46:J46) -> 1
A47: Vigas transversales | B47: 161 | D47: =+VLOOKUP(B47,$C$73:$J$184,7,FALSE) -> kg | J47: 1 | K47: =SUM(E47:J47) -> 1
A48: Arriostres de Acero | B48: 117 | D48: =+VLOOKUP(B48,$C$73:$J$184,7,FALSE) -> kg | J48: 1 | K48: =SUM(E48:J48) -> 1
A49: Elevacion cuerpo estribo de Conc. Armado | B49: 202 | D49: =+VLOOKUP(B49,$C$73:$J$184,7,FALSE) -> m3 | J49: 1 | K49: =SUM(E49:J49) -> 1
A50: Elevacion Alas de Estribo de Conc. Armado | B50: 205 | D50: =+VLOOKUP(B50,$C$73:$J$184,7,FALSE) -> m3 | J50: 1 | K50: =SUM(E50:J50) -> 1
A51: Capa de Asfalto | B51: 301 | D51: =+VLOOKUP(B51,$C$73:$J$184,7,FALSE) -> m2 | J51: 1 | K51: =SUM(E51:J51) -> 1
A52: Señalizacion horizontal (pintura) | B52: 501 | D52: =+VLOOKUP(B52,$C$73:$J$184,7,FALSE) -> und. | J52: 1 | K52: =SUM(E52:J52) -> 1
A53: Vereda de concreto | B53: 311 | D53: =+VLOOKUP(B53,$C$73:$J$184,7,FALSE) -> m2 | J53: 1 | K53: =SUM(E53:J53) -> 1
...

Sheet sec F
C4: PUENTE AGUA BLANCA
C6: Puente : | D6: =+'F.- ELEMENTOS'!E7 -> PUENTE AGUA BLANCA | F6: Ruta : | G6: =+'A-D.- FICHA'!P15 -> MO-100 | I6: Progresiva: | K6: =+'A-D.- FICHA'!P17 -> 30298
C8: F.2 :CONDICION GLOBAL DEL PUENTE
D11: 1 | E11: Bueno | G11: 3 | H11: Preocupante | J11: 5 | K11: Pesimo
D13: 0 | E13: Excelente | G13: 2 | H13: Regular | J13: 4 | K13: Malo
C15: Inspector | D15: M.Sc. Ing. Nelson Pareja | H15: Fecha de Inspeccion | K15: ='A-D.- FICHA'!N31 -> 45715
C16: Supervisor | H16: Fecha de Revision
C19: Elemento | F19: Descripcion
B21: I. SUPERESTRUCTURA
B22: 104 | C22: =+VLOOKUP(B22,elementos,3,FALSE) -> Losa de concreto armado (Refuerzo Transversal) | F22: Se observa eflorescencia y rastros de humedad en las salidas de las tuberías de drenaje, lo que indica posibles filtraciones o deficiencias en el sistema de evacuación de aguas.
B23: 110 | C23: =+VLOOKUP(B23,elementos,3,FALSE) -> Viga Principales concreto armado | F23: Se identifican fisuras diagonales en la viga aguas abajo, cerca del estribo derecho. Además, el concreto presenta decoloración y acumulación de polvo en la superficie.
B24: 111 | C24: =+VLOOKUP(B24,elementos,3,FALSE) -> Vigas Secundarias de concreto armado | F24: Se detectan fisuras verticales en la viga diafragma cercana al estribo derecho. Asimismo, se observa decoloración del concreto y polvo adherido en la superficie.
B25: II. SUBESTRUCTURA
B26: 202 | C26: =+VLOOKUP(B26,elementos,3,FALSE) -> Elevación Cuerpo del Estribo de Concreto Armado | F26: Se observa decoloración del concreto y acumulación de polvo en la superficie. Se evidencian fisuras verticales en la pantalla del estribo derecho.
B27: 205 | C27: =+VLOOKUP(B27,elementos,3,FALSE) -> Elevación Alas del Estribo de Concreto Armado | F27: Se observa decoloración del concreto y acumulación de polvo en la superficie. Además, se presentan rastros de eflorescencia, principalmente en el ala aguas arriba del estribo izquierdo.
B28: III. DETALLES | P28: Elevación de Pilares Concreto Armado
B29: 302 | C29: =+VLOOKUP(B29,elementos,3,FALSE) -> Capa Concreto Pobre | F29: Se ha acumulado material de relleno a lo largo de la superficie de rodadura, llegando hasta el borde superior de la vereda. Esto ha generado encharcamiento de agua en la superficie de rodadura, además de obstrucción parcial y total en el ingreso del sistema de drenaje.
B30: 311 | C30: =+VLOOKUP(B30,elementos,3,FALSE) -> Vereda Concreto | F30: Las veredas están parcial y totalmente cubiertas por el material de relleno. En la zona aguas arriba, parte de la vereda se encuentra fracturada. Adicionalmente, se observan fisuras por retracción del concreto.
B31: 353 | C31: =+VLOOKUP(B31,elementos,3,FALSE) -> Barandas de Acero | F31: Los elementos metálicos que conforman la baranda (postes y pasamanos) presentan polvo adherido en la superficie, pérdida parcial de pintura y signos de oxidación superficial.
B32: 372 | C32: =+VLOOKUP(B32,elementos,3,FALSE) -> Tuberías PVC | F32: Los ingresos de las tuberías de drenaje se encuentran parcial o totalmente obstruidos por el material de relleno acumulado en las márgenes de la vía. Además, las salidas de los tubos de PVC están al ras del fondo de la losa, lo que ha generado eflorescencia y humedad en el área circundante.
B33: IV. CAUCE
B34: 401 | C34: =+VLOOKUP(B34,elementos,3,FALSE) -> Márgenes del río | F34: En su mayoría, las márgenes están bien definidas, ya que el terreno es rocoso. Sin embargo, en la margen izquierda aguas abajo se encuentra material de relleno del talud de la carretera, el cual es altamente erosionable.
B35: 402 | C35: =+VLOOKUP(B35,elementos,3,FALSE) -> Lecho del río | F35: Se presenta un caudal torrentoso que transporta material de gran tamaño, lo que podría generar cambios en la estabilidad del cauce en eventos de alta precipitación.
B36: V. ACCESOS
B37: 501 | C37: =+VLOOKUP(B37,elementos,3,FALSE) -> Señalización | F37: Solo se cuenta con un cartel informativo en el acceso izquierdo, indicando el nombre, la longitud y la capacidad máxima del puente. No se dispone de señalización preventiva, reglamentaria ni horizontal.
B38: 511 | C38: =+VLOOKUP(B38,elementos,3,FALSE) -> Pavimento/Afirmado | F38: En el acceso izquierdo se ha acumulado una gran cantidad de material de relleno, lo que dificulta la transitabilidad. Además, se observan cárcavas que afectan la estabilidad del acceso.
B39: 530 | C39: =+VLOOKUP(B39,elementos,3,FALSE) -> Visibilidad | F39: Debido al alineamiento curvo en los accesos, la visibilidad desde el puente es regular, lo que podría representar un riesgo para la circulación vehicular.
B41: =+'A-D.- FICHA'!C47 -> Evaluación : Ing. Martín Pichón

Sheet F.2.-PANEL FOTOGRAFICO
G1: NUMERO DE FOTOS | H1: 2
B3: SECCION (F) CONDICION DEL PUENTE | XFD3: SI
C4: PUENTE AGUA BLANCA | G4: Importar de forma manual? | XFD4: NO
B5: F.2 PANEL FOTOGRAFICO | H5: NO
B7: NOMBRE | D7: =+'A-D.- FICHA'!J9 -> PUENTE AGUA BLANCA
B8: RUTA | D8: =+'A-D.- FICHA'!P15 -> MO-100
B9: PROGRESIVA | D9: =+'A-D.- FICHA'!P17 -> 30298
B11: LISTA DE FOTOGRAFIAS
B12: NRO. | C12: FECHA | D12: DESCRIPCION | E12: DIGITAL
B13: 1 | C13: 45715 | D13: ACCESO IZQUIERDO: Debido al alineamiento curvo la visibilidad desde el puente es regular, lo que podría representar un riesgo para la circulación vehicular.
B14: 2 | C14: 45715 | D14: AFIRMADO ACCESO IZQUIERDO: En el acceso izquierdo se ha acumulado una gran cantidad de material de relleno, lo que dificulta la transitabilidad. Además, se observan cárcavas que afectan la estabilidad del acceso.
B15: 3 | C15: 45715 | D15: ACCESO DERECHO: Debido al alineamiento curvo la visibilidad desde el puente es regular, lo que podría representar un riesgo para la circulación vehicular.
B16: 4 | C16: 45715 | D16: AFIRMADO ACCESO DERECHO: No se observa daños en el afirmado del acceso derecho.
B17: 5 | C17: 45715 | D17: SUPERFICIE DE RODARURA: Se ha acumulado material de relleno a lo largo de la superficie de rodadura, llegando hasta el borde superior de la vereda. Esto ha generado encharcamiento de agua en la superficie de rodadura, además de obstrucción parcial y total en el ingreso del sistema de drenaje.
B18: 6 | C18: 45715 | D18: AGUAS ARRIBA: Márgenes están bien definidas, ya que el terreno es rocoso. Se presenta un caudal torrentoso que transporta material de gran tamaño, lo que podría generar cambios en la estabilidad del cauce en eventos de alta precipitación.
B19: 7 | C19: 45715 | D19: AGUAS ABAJO: Margen izquierda aguas abajo se encuentra material de relleno del talud de la carretera, el cual es altamente erosionable. Se presenta un caudal torrentoso que transporta material de gran tamaño, lo que podría generar cambios en la estabilidad del cauce en eventos de alta precipitación.
B20: 8 | C20: 45715 | D20: ALA IZQUIERDA AGUAS ARRIBA: Se observa decoloración del concreto y acumulación de polvo en la superficie. Además, se presentan rastros de eflorescencia.
B21: 9 | C21: 45715 | D21: ALA DERECHA AGUAS ARRIBA: Se observa decoloración del concreto y acumulación de polvo en la superficie. Además, se presentan rastros de eflorescencia.
B22: 10 | C22: 45715 | D22: ALA IZQUIERDA AGUAS ABAJO: Se observa decoloración del concreto y acumulación de polvo en la superficie. Además, se presentan rastros de eflorescencia.
B23: 11 | C23: 45715 | D23: ALA DERECHA AGUAS ABAJO: Se observa decoloración del concreto y acumulación de polvo en la superficie. Además, se presentan rastros de eflorescencia.
B24: 12 | C24: 45715 | D24: PANTALLA DE ESTRIBO IZQUIERDO: Se observa decoloración del concreto y acumulación de polvo en la superficie.
... B44: 32 | C44: 45715 | D44: SEÑAL INFORMATIVA DEL ACCESO IZQUIERDO: Solo se cuenta con un cartel informativo en el acceso izquierdo, indicando el nombre, la longitud y la capacidad máxima del puente. Los postes con picaduras de oxido.

Sheet G.- CONDICION ESTADISTICA
A3: =+'A-D.- FICHA'!C4 -> PUENTE AGUA BLANCA
C4: PUENTE AGUA BLANCA
A5: G.1 : CONDICION ESTADISTICA DEL PUENTE
A7: =+CONCATENATE("NOMBRE: ",'A-D.- FICHA'!J9) -> NOMBRE: PUENTE AGUA BLANCA | D7: Ruta: | E7: =+'A-D.- FICHA'!P15 -> MO-100 | I7: PROGRESIVA : | L7: =+'A-D.- FICHA'!P17 -> 30298
A9: tabla 1
A10: CODIGO | B10: DESCRIPCION | C10: METRADO | D10: UND. | E10: Factor de Importancia | F10: CALIFICACION (%) | L10: CONDICION ESTADISTICA DEL PUENTE
F11: 0 | G11: 1 | H11: 2 | I11: 3 | J11: 4 | K11: 5
F12: Muy Bueno | G12: Bueno | H12: Satisfactorio | I12: Marginal | J12: Pobre | K12: Muy Pobre | M12: =IF(L13>4,"MUY MALO",IF(L13>3,"MALO",IF(L13>2,"REGULAR","BUENO"))) -> REGULAR
L13: =+E191 -> 2.070086 | N13: verificaciones
A14: 104 | B14: =+IF(A14=0," ",VLOOKUP(A14,'F.- ELEMENTOS'!$C$73:$E$184,3)) -> Losa de concreto armado (Refuerzo Transversal) | C14: =4.7*0.2*31.2 -> 29.328 | D14: =+IF(A14=0," ",VLOOKUP(A14,'F.- ELEMENTOS'!$C$73:$I$184,7)) -> m3 | E14: =+IF(A14=0,,VLOOKUP(A14,'F.- ELEMENTOS'!$C$73:$J$184,8)) -> 0.6 | G14: 100 | N14: =SUM(F14:K14) -> 100 | O14: =+IF(N14<=100,+IF(N14=100,"Ok",""),"se pasa") -> Ok
A15: 110 | B15: =+IF(A15=0," ",VLOOKUP(A15,'F.- ELEMENTOS'!$C$73:$E$184,3)) -> Viga Principales concreto armado | C15: =66.05*0.5*2 -> 66.05 | D15: =+IF(A15=0," ",VLOOKUP(A15,'F.- ELEMENTOS'!$C$73:$I$184,7)) -> m3 | E15: =+IF(A15=0,,VLOOKUP(A15,'F.- ELEMENTOS'!$C$73:$J$184,8)) -> 1 | G15: 90 | H15: 10 | N15: =SUM(F15:K15) -> 100 | O15: =+IF(N15<=100,+IF(N15=100,"Ok",""),"se pasa") -> Ok
A16: 111 | B16: =+IF(A16=0," ",VLOOKUP(A16,'F.- ELEMENTOS'!$C$73:$E$184,3)) -> Vigas Secundarias de concreto armado | C16: =0.375*5*3.5 -> 6.5625 | D16: =+IF(A16=0," ",VLOOKUP(A16,'F.- ELEMENTOS'!$C$73:$I$184,7)) -> m3 | E16: =+IF(A16=0,,VLOOKUP(A16,'F.- ELEMENTOS'!$C$73:$J$184,8)) -> 0.8 | G16: 100 | N16: =SUM(F16:K16) -> 100 | O16: =+IF(N16<=100,+IF(N16=100,"Ok",""),"se pasa") -> Ok
A17: 202 | B17: =+IF(A17=0," ",VLOOKUP(A17,'F.- ELEMENTOS'!$C$73:$E$184,3)) -> Elevación Cuerpo del Estribo de Concreto Armado | C17: =12.78*2*4.7 -> 120.132 | D17: =+IF(A17=0," ",VLOOKUP(A17,'F.- ELEMENTOS'!$C$73:$I$184,7)) -> m3 | E17: =+IF(A17=0,,VLOOKUP(A17,'F.- ELEMENTOS'!$C$73:$J$184,8)) -> 1 | G17: 100 | N17: =SUM(F17:K17) -> 100 | O17: =+IF(N17<=100,+IF(N17=100,"Ok",""),"se pasa") -> Ok
A18: 205 | B18: =+IF(A18=0," ",VLOOKUP(A18,'F.- ELEMENTOS'!$C$73:$E$184,3)) -> Elevación Alas del Estribo de Concreto Armado | C18: =3.5*0.3*5.3*4 -> 22.26 | D18: =+IF(A18=0," ",VLOOKUP(A18,'F.- ELEMENTOS'!$C$73:$I$184,7)) -> m3 | E18: =+IF(A18=0,,VLOOKUP(A18,'F.- ELEMENTOS'!$C$73:$J$184,8)) -> 0.6 | G18: 100 | N18: =SUM(F18:K18) -> 100 | O18: =+IF(N18<=100,+IF(N18=100,"Ok",""),"se pasa") -> Ok
A19: 302 | B19: =+IF(A19=0," ",VLOOKUP(A19,'F.- ELEMENTOS'!$C$73:$E$184,3)) -> Capa Concreto Pobre | C19: =31.2*3.5 -> 109.2 | D19: =+IF(A19=0," ",VLOOKUP(A19,'F.- ELEMENTOS'!$C$73:$I$184,7)) -> m2 | E19: =+IF(A19=0,,VLOOKUP(A19,'F.- ELEMENTOS'!$C$73:$J$184,8)) -> 0.4 | G19: 100 | N19: =SUM(F19:K19) -> 100 | O19: =+IF(N19<=100,+IF(N19=100,"Ok",""),"se pasa") -> Ok
A20: 311 | B20: =+IF(A20=0," ",VLOOKUP(A20,'F.- ELEMENTOS'!$C$73:$E$184,3)) -> Vereda Concreto | C20: =31.2*0.6*2 -> 37.44 | D20: =+IF(A20=0," ",VLOOKUP(A20,'F.- ELEMENTOS'!$C$73:$I$184,7)) -> m2 | E20: =+IF(A20=0,,VLOOKUP(A20,'F.- ELEMENTOS'!$C$73:$J$184,8)) -> 0.2 | G20: 90 | I20: 10 | N20: =SUM(F20:K20) -> 100 | O20: =+IF(N20<=100,+IF(N20=100,"Ok",""),"se pasa") -> Ok
A21: 353 | B21: =+IF(A21=0," ",VLOOKUP(A21,'F.- ELEMENTOS'!$C$73:$E$184,3)) -> Barandas de Acero | C21: =2*31.2 -> 62.4 | D21: =+IF(A21=0," ",VLOOKUP(A21,'F.- ELEMENTOS'!$C$73:$I$184,7)) -> ml | E21: =+IF(A21=0,,VLOOKUP(A21,'F.- ELEMENTOS'!$C$73:$J$184,8)) -> 0.4 | G21: 100 | N21: =SUM(F21:K21) -> 100 | O21: =+IF(N21<=100,+IF(N21=100,"Ok",""),"se pasa") -> Ok
A22: 372 | B22: =+IF(A22=0," ",VLOOKUP(A22,'F.- ELEMENTOS'!$C$73:$E$184,3)) -> Tuberías PVC | C22: 12 | D22: =+IF(A22=0," ",VLOOKUP(A22,'F.- ELEMENTOS'!$C$73:$I$184,7)) -> und. | E22: =+IF(A22=0,,VLOOKUP(A22,'F.- ELEMENTOS'!$C$73:$J$184,8)) -> 0.4 | I22: 100 | N22: =SUM(F22:K22) -> 100 | O22: =+IF(N22<=100,+IF(N22=100,"Ok",""),"se pasa") -> Ok
A23: 401 | B23: =+IF(A23=0," ",VLOOKUP(A23,'F.- ELEMENTOS'!$C$73:$E$184,3)) -> Márgenes del río | C23: 500 | D23: =+IF(A23=0," ",VLOOKUP(A23,'F.- ELEMENTOS'!$C$73:$I$184,7)) -> ml | E23: =+IF(A23=0,,VLOOKUP(A23,'F.- ELEMENTOS'!$C$73:$J$184,8)) -> 0.6 | G23: 75 | H23: 25 | N23: =SUM(F23:K23) -> 100 | O23: =+IF(N23<=100,+IF(N23=100,"Ok",""),"se pasa") -> Ok
A24: 402 | B24: =+IF(A24=0," ",VLOOKUP(A24,'F.- ELEMENTOS'!$C$73:$E$184,3)) -> Lecho del río | C24: 250 | D24: =+IF(A24=0," ",VLOOKUP(A24,'F.- ELEMENTOS'!$C$73:$I$184,7)) -> ml | E24: =+IF(A24=0,,VLOOKUP(A24,'F.- ELEMENTOS'!$C$73:$J$184,8)) -> 0.6 | G24: 100 | N24: =SUM(F24:K24) -> 100 | O24: =+IF(N24<=100,+IF(N24=100,"Ok",""),"se pasa") -> Ok
A25: 501 | B25: =+IF(A25=0," ",VLOOKUP(A25,'F.- ELEMENTOS'!$C$73:$E$184,3)) -> Señalización | C25: 1 | D25: =+IF(A25=0," ",VLOOKUP(A25,'F.- ELEMENTOS'!$C$73:$I$184,7)) -> und. | E25: =+IF(A25=0,,VLOOKUP(A25,'F.- ELEMENTOS'!$C$73:$J$184,8)) -> 0.2 | G25: 100 | N25: =SUM(F25:K25) -> 100 | O25: =+IF(N25<=100,+IF(N25=100,"Ok",""),"se pasa") -> Ok
A26: 511 | B26: =+IF(A26=0," ",VLOOKUP(A26,'F.- ELEMENTOS'!$C$73:$E$184,3)) -> Pavimento/Afirmado | C26: =2*10*3.5 -> 70 | D26: =+IF(A26=0," ",VLOOKUP(A26,'F.- ELEMENTOS'!$C$73:$I$184,7)) -> m2 | E26: =+IF(A26=0,,VLOOKUP(A26,'F.- ELEMENTOS'!$C$73:$J$184,8)) -> 0.2 | G26: 50 | I26: 50 | N26: =SUM(F26:K26) -> 100 | O26: =+IF(N26<=100,+IF(N26=100,"Ok",""),"se pasa") -> Ok
A27: 530 | B27: =+IF(A27=0," ",VLOOKUP(A27,'F.- ELEMENTOS'!$C$73:$E$184,3)) -> Visibilidad | C27: 40 | D27: =+IF(A27=0," ",VLOOKUP(A27,'F.- ELEMENTOS'!$C$73:$I$184,7)) -> ml | E27: =+IF(A27=0,,VLOOKUP(A27,'F.- ELEMENTOS'!$C$73:$J$184,8)) -> 0.2 | H27: 100 | N27: =SUM(F27:K27) -> 100 | O27: =+IF(N27<=100,+IF(N27=100,"Ok",""),"se pasa") -> Ok
N28: =SUM(F28:K28) -> 0 | O28: =+IF(N28<=100,+IF(N28=100,"Ok",""),"se pasa")
N29: =SUM(F29:K29) -> 0 | O29: =+IF(N29<=100,+IF(N29=100,"Ok",""),"se pasa")
N30: =SUM(F30:K30) -> 0 | O30: =+IF(N30<=100,+IF(N30=100,"Ok",""),"se pasa")
N31: =SUM(F31:K31) -> 0 | O31: =+IF(N31<=100,+IF(N31=100,"Ok",""),"se pasa")
N32: =SUM(F32:K32) -> 0 | O32: =+IF(N32<=100,+IF(N32=100,"Ok",""),"se pasa")
N33: =SUM(F33:K33) -> 0 | O33: =+IF(N33<=100,+IF(N33=100,"Ok",""),"se pasa")
N34: =SUM(F34:K34) -> 0 | O34: =+IF(N34<=100,+IF(N34=100,"Ok",""),"se pasa")
N35: =SUM(F35:K35) -> 0 | O35: =+IF(N35<=100,+IF(N35=100,"Ok",""),"se pasa")
B36: =+IF(A36=0," ",VLOOKUP(A36,'F.- ELEMENTOS'!$C$73:$E$184,3)) | D36: =+IF(A36=0," ",VLOOKUP(A36,'F.- ELEMENTOS'!$C$73:$I$184,7)) | N36: =SUM(F36:K36) -> 0 | O36: =+IF(N36<=100,+IF(N36=100,"Ok",""),"se pasa")
B37: =+IF(A37=0," ",VLOOKUP(A37,'F.- ELEMENTOS'!$C$73:$E$184,3)) | D37: =+IF(A37=0," ",VLOOKUP(A37,'F.- ELEMENTOS'!$C$73:$I$184,7))
B38: =+IF(A38=0," ",VLOOKUP(A38,'F.- ELEMENTOS'!$C$73:$E$184,3)) | D38: =+IF(A38=0," ",VLOOKUP(A38,'F.- ELEMENTOS'!$C$73:$I$184,7))
B39: =+IF(A39=0," ",VLOOKUP(A39,'F.- ELEMENTOS'!$C$73:$E$184,3)) | D39: =+IF(A39=0," ",VLOOKUP(A39,'F.- ELEMENTOS'!$C$73:$I$184,7))
B40: =+IF(A40=0," ",VLOOKUP(A40,'F.- ELEMENTOS'!$C$73:$E$184,3)) | D40: =+IF(A40=0," ",VLOOKUP(A40,'F.- ELEMENTOS'!$C$73:$I$184,7))
B41: =+IF(A41=0," ",VLOOKUP(A41,'F.- ELEMENTOS'!$C$73:$E$184,3)) | D41: =+IF(A41=0," ",VLOOKUP(A41,'F.- ELEMENTOS'!$C$73:$I$184,7))
B42: =+IF(A42=0," ",VLOOKUP(A42,'F.- ELEMENTOS'!$C$73:$E$184,3)) | D42: =+IF(A42=0," ",VLOOKUP(A42,'F.- ELEMENTOS'!$C$73:$I$184,7))
B43: =+IF(A43=0," ",VLOOKUP(A43,'F.- ELEMENTOS'!$C$73:$E$184,3)) | D43: =+IF(A43=0," ",VLOOKUP(A43,'F.- ELEMENTOS'!$C$73:$I$184,7))
B44: =+IF(A44=0," ",VLOOKUP(A44,'F.- ELEMENTOS'!$C$73:$E$184,3)) | D44: =+IF(A44=0," ",VLOOKUP(A44,'F.- ELEMENTOS'!$C$73:$I$184,7))
...

Sheet CONCLUSIONES
B4: FICHA SCAP
B6: SECCION (G): RESUMEN DE LA CONDICION DEL PUENTE Y RECOMENDACIONES
C9: G.2 : OBSERVACIONES Y RECOMENDACIONES
B12: NOMBRE | D12: =+Hoja3!C11 -> PUENTE AGUA BLANCA
B13: RUTA | D13: =+Hoja3!C7 -> MO-100
B14: PROGRESIVA | D14: =+Hoja3!C10 -> 30298
B17: OBSERVACIONES | F17: RECOMENDACIONES
B18: ACCIONES NORMATIVAS :
B19: =_xlfn.CONCAT("De acuerdo a la evaluación realizada al ",'A-D.- FICHA'!J9:L9," y a los terminos de referencia (Gestión y relevamiento de Puentes); de ser necesario, corresponde realizar acciones normativas.") -> De acuerdo a la evaluación realizada al PUENTE AGUA BLANCA y a los terminos de referencia (Gestión y relevamiento de Puentes); de ser necesario, corresponde realizar acciones normativas.
B28: ACCIONES PREVENTIVAS :
B29: =+_xlfn.CONCAT("De acuerdo a la evaluación realizada al Puente ",'A-D.- FICHA'!J9:L9," y a los terminos de referencia (Gestión y Relevamiento de Puentes); de ser necesario, corresponde realizar acciones preventivas.") -> De acuerdo a la evaluación realizada al Puente PUENTE AGUA BLANCA y a los terminos de referencia (Gestión y Relevamiento de Puentes); de ser necesario, corresponde realizar acciones preventivas. | E29: Se recomienda que se cumpla con las especificaciones técnicas de los materiales y el procedimiento adecuado de las actividades de conservación rutinaria y periodica. Al concluir el periodo de intervención se recomienda programar periódicamente el mantenimiento de los puentes.
B38: ACCIONES EJECUTIVAS :
B39: =_xlfn.CONCAT("De la inspeccion realizada podemos indicar las siguientes conclusiones:", " La evaluación de la condición estadística del ",'A-D.- FICHA'!J9:L9, ", efectuada bajo la metodología SCAP señala que el puente se encuentra en la calificación ",'G.- CONDICION ESTADISTICA'!M12," requiriéndose realizar el mantenimiento rutinario a fin de mejorar e incrementar su vida útil, a continuacion detallamos las acciones a realizar.") -> De la inspeccion realizada podemos indicar las siguientes conclusiones: La evaluación de la condición estadística del PUENTE AGUA BLANCA, efectuada bajo la metodología SCAP señala que el puente se encuentra en la calificación REGULAR requiriéndose realizar el mantenimiento rutinario a fin de mejorar e incrementar su vida útil, a continuacion detallamos las acciones a realizar. | E39: =_xlfn.CONCAT("De la inspección realizada podemos indicar las siguientes conclusiones:"," Realizar el mantenimiento periodico a fin de mejorar e incrementar la vida útil del ",'A-D.- FICHA'!J9:L9,", a continuacion detallamos las acciones a realizar.") -> De la inspección realizada podemos indicar las siguientes conclusiones: Realizar el mantenimiento periodico a fin de mejorar e incrementar la vida útil del PUENTE AGUA BLANCA, a continuacion detallamos las acciones a realizar.
B43: • Limpieza roce y desbroce. • Limpieza de puentes. • Reparación de deterioros superficiales en elementos de concreto. • Reparación de fisuras y grietas en elementos de concreto. • Conservación de barandas. • Conservación de pintado de veredas, sardineles y muros de puentes. | E43: • Limpieza de superficies de puente de concreto. • Tratamiento con pintura cementicia con aditivo antibacterial. • Pintado de elementos de puentes de concreto. • Ampliación y/o reemplazo de drenajes.
B56: FECHA INSPECCION : | D56: ='A-D.- FICHA'!N31 -> 45715
B57: INSPECTOR : | D57: Ing. Martín Pichón.
H58: FIRMA

Sheet AUXILIAR
B3: ELLEMENTOS CONFORMANTES DE UN PUENTE Y SU IMPORTANCIA
B4: Item | C4: Codif. Elemento | D4: 1 | E4: Unidad | F4: Factor Importancia | G4: ELEMENTO
B5: 1 | C5: 101 | D5: Losa de concreto armado (Refuerzo longitudinal) | E5: m3 | F5: 1 | G5: SUPERESTRUCTURA
B6: =1+B5 -> 2 | C6: 102 | D6: Losa de concreto pretensado (Pretensado Longitudinal) | E6: m3 | F6: 1 | G6: SUPERESTRUCTURA | I6: MACRO
B7: =1+B6 -> 3 | C7: 103 | D7: Losa de Concreto Simple | E7: m3 | F7: 0.6 | G7: SUPERESTRUCTURA
B8: =1+B7 -> 4 | C8: 104 | D8: Losa de concreto armado (Refuerzo Transversal) | E8: m3 | F8: 0.6 | G8: SUPERESTRUCTURA
B9: =1+B8 -> 5 | C9: 105 | D9: Losa de concreto pretensado (Pretensado Transversal) | E9: m3 | F9: 0.6 | G9: SUPERESTRUCTURA
B10: =1+B9 -> 6 | C10: 106 | D10: Plancha Metálica Corrugada | E10: m2 | F10: 0.6 | G10: SUPERESTRUCTURA
B11: =1+B10 -> 7 | C11: 107 | D11: Tablero de Madera | E11: ft.2 | F11: 0.6 | G11: SUPERESTRUCTURA
B12: =1+B11 -> 8 | C12: 110 | D12: Viga Principales concreto armado | E12: m3 | F12: 1 | G12: SUPERESTRUCTURA
B13: =1+B12 -> 9 | C13: 111 | D13: Vigas Secundarias de concreto armado | E13: m3 | F13: 0.8 | G13: SUPERESTRUCTURA
B14: =1+B13 -> 10 | C14: 112 | D14: Vigas Principales de concreto pretensado | E14: m3 | F14: 1 | G14: SUPERESTRUCTURA
B15: =1+B14 -> 11 | C15: 113 | D15: Vigas Secundarias de concreto Pretensado | E15: m3 | F15: 0.8 | G15: SUPERESTRUCTURA
B16: =1+B15 -> 12 | C16: 114 | D16: Vigas Principales de Acero Estructural | E16: kg | F16: 1 | G16: SUPERESTRUCTURA
B17: =1+B16 -> 13 | C17: 115 | D17: Vigas Secundarias de Acero | E17: kg | F17: 0.8 | G17: SUPERESTRUCTURA
B18: =1+B17 -> 14 | C18: 116 | D18: Vigas de Madera | E18: ft.2 | F18: 1 | G18: SUPERESTRUCTURA
... B116: =1+B115 -> 112 | C116: 530 | D116: Visibilidad | E116: ml | F116: 0.2 | G116: ACCESOS

Sheet Hoja1
E2: GUIA PARA LA INSPECCION, EVALUACION Y MANTENIMIENTO DE PUENTES
A6: METODOLOGÍA PARA EVALUACION DE PUENTES
A8: CONDICION ESTADISTICA DE LOS ELEMENTOS Y DEL PUENTE
A10: Algoritmos para el análisis.
A12: En esta sección se describe los principales criterios empleados para las opciones de análisis. Los criterios y metodologías, se utilizan al escribir los códigos.
A15: 1 - Concepto de condición estadística
A17: Está sección del presente Manual contiene una explicación y fundamentación ampliada respecto a los procedimientos de cálculo para encontrar un numero que califique la condición, sea de un elemento como del puente.
A21: Se introduce el concepto de condición estadística, como aquel numero que califique la situación del puente y de cada uno de sus elementos. Este valor se deduce de la condición en campo, que corresponde a varios números, expresados en la forma de porcentajes de la situación del elemento en la escala de 0 a 5.
A26: En la condición en campo, la situación del elemento está definida por porcentajes, uno para cada escala. Está condición, está relacionada directamente con las necesidades de reparación o sustitución del elemento.
A30: La condición estadística, corresponde a un solo número que calificaría situación integral del elemento. Es utilizada para el cálculo de la condición del puente, y de ahí para la priorización. Obsérvese que puede darse el caso de varias condiciones de campo que conduzcan a un mismo valor de condición estadística.
A35: En esta sección se describen los criterios y metodologías empleados para las opciones de análisis.
A37: 2 - Condición estadística de un elemento
A39: Como se menciono, se introduce el concepto de condición estadística que simplifica en un número, la información de la condición del elemento proveniente, del trabajo de campo.
A42: La condición del elemento evaluada en campo, se expresa, según se ilustra en la Tabla 1, para un puente hipotético, como porcentajes para cada nivel de condición, desde 0 (muy bueno), hasta 5 (muy pobre). Así, el elemento 101, tiene el 10% en calidad satisfactoria, el 40% como bueno y el 50% como muy bueno.
B47: Tabla 1
B48: Ejemplo para la condición de cuatro elementos de un puente, según evaluación de campo.
B49: Porcentajes de la condición para cada elemento
A50: Elemento | C50: Nivel de la condición
C51: 5 | D51: 4 | E51: 3 | F51: 2 | G51: 1 | H51: 0 | I51: Total %
C52: Muy pobre | D52: Pobre | E52: Marginal | F52: Satisfactorio | G52: Bueno | H52: Muy Bueno
A53: 101 | C53: 0 | D53: 0 | E53: 0 | F53: 10 | G53: 40 | H53: 50 | I53: =SUM(C53:H53) -> 100
A54: 201 | C54: 0 | D54: 20 | E54: 20 | F54: 20 | G54: 20 | H54: 20 | I54: =SUM(C54:H54) -> 100
A55: 301 | C55: 10 | D55: 20 | E55: 50 | F55: 20 | G55: 0 | H55: 0 | I55: =SUM(C55:H55) -> 100
A56: 401 | C56: 2 | D56: 10 | E56: 28 | F56: 30 | G56: 20 | H56: 10 | I56: =SUM(C56:H56) -> 100
A57: 501 | C57: 0 | D57: 0 | E57: 40 | F57: 30 | G57: 20 | H57: 10 | I57: =SUM(C57:H57) -> 100
A59: La intención es expresar está situación dispersa, en un solo número que represente la condición global de cada elemento. EI procedimiento adoptado por el SCAP, es como sigue:
A63: UNIDAD GERENCIAL DE CONSERVACION | I63: 192
A64: AREA DE CONSERVACION DE PUENTES
E67: GUIA PARA LA INSPECCION, EVALUACION Y MANTENIMIENTO DE PUENTES
A71: 2.1 | B71: EI primer paso corresponde a ajustar la distribución de porcentajes, a condiciones umbral. Este ajuste se basa en la percepción, de que si un porcentaje significativo de un elemento está en un nivel dado de condición, entonces el elemento debiera ser evaluado como si totalmente estuviera en esa condición. EI proceso de ajuste corresponde a dividir el porcentaje de distribución de campo por aquel del umbral, y multiplicar el resultado por 100.
B77: Adoptamos un umbral del 3% para el nivel de condición 5, y 25% para los otros estados. Esto significa, por ejemplo, que basta que el 3% del elemento este en la condición 5 (muy pobre), para considerar está situación como la del total del elemento.
B81: Igualmente, si el 25% del elemento está en la condición 4 (pobre), está será la condición del elemento.
B84: El resultado del primer paso para el ejemplo, se muestra en la siguiente Tabla 2.
B86: Tabla 2
B87: Ajustes según porcentaje de umbral (%campo * 100 / %umbral)
B88: Porcentajes ajustados de la condición para cada elemento
A89: Elemento | C89: Nivel de la condición
C90: 5 | D90: 4 | E90: 3 | F90: 2 | G90: 1 | H90: 0 | L90: 5 | M90: 4 | N90: 3 | O90: 2 | P90: 1 | Q90: 0
C91: Muy pobre | D91: Pobre | E91: Marginal | F91: Satisfactorio | G91: Bueno | H91: Muy Bueno | L91: Muy pobre | M91: Pobre | N91: Marginal | O91: Satisfactorio | P91: Bueno | Q91: Muy Bueno
A92: 101 | C92: =ROUNDDOWN(+C53*100/3,0) -> 0 | D92: =ROUNDDOWN(+D53*100/25,0) -> 0 | E92: =ROUNDDOWN(+E53*100/25,0) -> 0 | F92: =ROUNDDOWN(+F53*100/25,0) -> 40 | G92: =ROUNDDOWN(+G53*100/25,0) -> 160 | H92: =ROUNDDOWN(+H53*100/25,0) -> 200 | L92: =+C92 -> 0 | M92: =+C92+D92 -> 0 | N92: =+C92+D92+E92 -> 0 | O92: =+C92+D92+E92+F92 -> 40 | P92: =+C92+D92+E92+F92+G92 -> 200 | Q92: =+C92+D92+E92+F92+G92+H92 -> 400
...

Sheet Hoja3
B2: UBICACIÓN GENERAL DEL PUENTE
B3: Distrito: | C3: =+'A-D.- FICHA'!J19 -> Matalaque
B4: Provincia: | C4: =+'A-D.- FICHA'!J17 -> Gral. Sanchez Cerro
B5: Departamento Político: | C5: =+'A-D.- FICHA'!J13 -> Moquegua
B6: Departamento Vial: | C6: =+'A-D.- FICHA'!J15 -> Moquegua
B7: Ruta: | C7: =+'A-D.- FICHA'!P15 -> MO-100
B8: Tipo de Ruta: | C8: =+'A-D.- FICHA'!P19 -> Departamental
B9: Tramo: | C9: =+'A-D.- FICHA'!E19 -> 11
B10: Progresiva: | C10: =+'A-D.- FICHA'!P17 -> 30298
B11: Puente: | C11: =+'A-D.- FICHA'!J9 -> PUENTE AGUA BLANCA
B12: DESCRIPCION DE LA SUPERESTRUCTURA
B13: Tipo: | C13: =+'A-D.- FICHA'!E78 -> Losa con Vigas
B14: Material: | C14: =+'A-D.- FICHA'!E84 -> Concreto armado
B15: N° de vanos: | C15: =+'A-D.- FICHA'!E62 -> 1
B16: Condición de borde: | C16: =+'A-D.- FICHA'!E82 -> Empotrado
B17: Longitud Total: | C17: =+'A-D.- FICHA'!E66 -> 31.2
B18: Calzada: | C18: =+'A-D.- FICHA'!E102 -> Concreto Pobre
B19: N° Vías: | C19: =+'A-D.- FICHA'!E33 -> 1
B20: Sobre Carga Diseño: | C20: =+'A-D.- FICHA'!E37 -> 0
B21: Espesor de Losa: | C21: =+'A-D.- FICHA'!E100 -> 0.2
B22: Eje de Viga(s) | C22: =+'A-D.- FICHA'!P104 -> 4
B23: Altura de Viga(s) | C23: =+'A-D.- FICHA'!J106 -> 1.65-2.95m
B24: N° Vigas | C24: =+'A-D.- FICHA'!J100 -> 2
B25: DESCRIPCCION DE LA INFRAESTRUCTURA
B26: Estribos: | C26: =+'A-D.- FICHA'!J120 -> Portico
B27: Pilares: | C27: =IF(+'A-D.- FICHA'!G183=0,"No aplica",+'A-D.- FICHA'!G183=0) -> No aplica
